<?xml version="1.0"?>
<robot xmlns:xacro="http://www.ros.org/wiki/xacro" >
    
    <xacro:include filename="materials.xacro" />
    <xacro:include filename="inertial_macros.xacro" />


    <!-- BASE LINK-->

    <link name="base_link">

    </link>

    <!-- CHASSIS LINK -->

    <joint name="chassis_joint" type="fixed">
        <parent link="base_link" />
        <child link="chassis" />
        <origin xyz="-0.33 0 0" />
    </joint>

    <link name="chassis">
        <visual>
            <origin xyz="0.33 0 0.1405" />
            <geometry>
                <box size="0.66 0.548 0.281" />
            </geometry>
            <material name="white" />
        </visual>
        <collision>
            <origin xyz="0.33 0 0.1405" />
            <geometry>
                <box size="0.66 0.548 0.281" />
            </geometry>
        </collision>
    </link>

    <!-- LEFT WHEEL LINK -->

    <joint name="left_wheel_joint" type="continuous">
        <parent link="base_link" />
        <child link="left_wheel" />
        <!-- CHANGE WHEEL OFFSET TO MATCH REAL ROBOT -->
        <origin xyz="0 0.25 0" rpy="${-pi/2} 0 0" />
        <axis xyz=" 0 0 1" />
    </joint>

    <link name="left_wheel">
        <visual>
            <geometry>
                <!-- CHANGE WHEEL RADIUS TO MATCH UP WITH REAL ROBOT FOR ODOM DATA -->
                <cylinder radius="0.05" length="0.04" />
            </geometry>
            <material name="blue" />
        </visual>
        <collision>
            <geometry>
                <!-- CHANGE WHEEL RADIUS TO MATCH UP WITH REAL ROBOT FOR ODOM DATA -->
                <cylinder radius="0.05" length="0.04" />
            </geometry>
        </collision>
    </link>

    <!-- RIGHT WHEEL LINK -->

    <joint name="right_wheel_joint" type="continuous">
        <parent link="base_link" />
        <child link="right_wheel" />
        <!-- CHANGE WHEEL OFFSET TO MATCH REAL ROBOT -->
        <origin xyz="0 -0.25 0" rpy="${pi/2} 0 0" />
        <axis xyz=" 0 0 -1" />
    </joint>

    <link name="right_wheel">
        <visual>
            <geometry>
                <!-- CHANGE WHEEL RADIUS TO MATCH UP WITH REAL ROBOT FOR ODOM DATA -->
                <cylinder radius="0.05" length="0.04" />
            </geometry>
            <material name="blue" />
        </visual>
        <collision>
            <geometry>
                <!-- CHANGE WHEEL RADIUS TO MATCH UP WITH REAL ROBOT FOR ODOM DATA -->
                <cylinder radius="0.05" length="0.04" />
            </geometry>
        </collision>
    </link>


    <!-- FRONT CASTER WHEEL LINK -->

    <joint name="front_caster_wheel_joint" type="fixed">
        <parent link="base_link" />
        <child link="front_caster_wheel" />
        <origin xyz="0.25 0 0" />
    </joint>

    <link name="front_caster_wheel">
        <visual>
            <geometry>
                <sphere radius="0.05" />
            </geometry>
            <material name="black" />
        </visual>
        <collision>
            <geometry>
                <sphere radius="0.05" />
            </geometry>
        </collision>
    </link>

    <!-- REAR CASTER WHEEL LINK -->

    <joint name="rear_caster_wheel_joint" type="fixed">
        <parent link="base_link" />
        <child link="rear_caster_wheel" />
        <origin xyz="-0.25 0 0" />
    </joint>

    <link name="rear_caster_wheel">
        <visual>
            <geometry>
                <sphere radius="0.05" />
            </geometry>
            <material name="black" />
        </visual>
        <collision>
            <geometry>
                <sphere radius="0.05" />
            </geometry>
        </collision>
    </link>

</robot>